Invalid HTTP_HOST header: 'store.innovestraenterprises.co.ke'. You may need to add 'store.innovestraenterprises.co.ke' to ALLOWED_HOSTS.
Traceback (most recent call last):
  File "/home/runezvdw/virtualenv/store.innovestraenterprises.co.ke/3.13/lib/python3.13/site-packages/django/core/handlers/exception.py", line 55, in inner
    response = get_response(request)
  File "/home/runezvdw/virtualenv/store.innovestraenterprises.co.ke/3.13/lib/python3.13/site-packages/django/utils/deprecation.py", line 119, in __call__
    response = self.process_request(request)
  File "/home/runezvdw/virtualenv/store.innovestraenterprises.co.ke/3.13/lib/python3.13/site-packages/django/middleware/common.py", line 48, in process_request
    host = request.get_host()
  File "/home/runezvdw/virtualenv/store.innovestraenterprises.co.ke/3.13/lib/python3.13/site-packages/django/http/request.py", line 202, in get_host
    raise DisallowedHost(msg)
django.core.exceptions.DisallowedHost: Invalid HTTP_HOST header: 'store.innovestraenterprises.co.ke'. You may need to add 'store.innovestraenterprises.co.ke' to ALLOWED_HOSTS.
Invalid HTTP_HOST header: 'store.innovestraenterprises.co.ke'. You may need to add 'store.innovestraenterprises.co.ke' to ALLOWED_HOSTS.
Traceback (most recent call last):
  File "/home/runezvdw/virtualenv/store.innovestraenterprises.co.ke/3.13/lib/python3.13/site-packages/django/core/handlers/exception.py", line 55, in inner
    response = get_response(request)
  File "/home/runezvdw/virtualenv/store.innovestraenterprises.co.ke/3.13/lib/python3.13/site-packages/django/utils/deprecation.py", line 119, in __call__
    response = self.process_request(request)
  File "/home/runezvdw/virtualenv/store.innovestraenterprises.co.ke/3.13/lib/python3.13/site-packages/django/middleware/common.py", line 48, in process_request
    host = request.get_host()
  File "/home/runezvdw/virtualenv/store.innovestraenterprises.co.ke/3.13/lib/python3.13/site-packages/django/http/request.py", line 202, in get_host
    raise DisallowedHost(msg)
django.core.exceptions.DisallowedHost: Invalid HTTP_HOST header: 'store.innovestraenterprises.co.ke'. You may need to add 'store.innovestraenterprises.co.ke' to ALLOWED_HOSTS.
Invalid HTTP_HOST header: 'store.innovestraenterprises.co.ke'. You may need to add 'store.innovestraenterprises.co.ke' to ALLOWED_HOSTS.
Traceback (most recent call last):
  File "/home/runezvdw/virtualenv/store.innovestraenterprises.co.ke/3.13/lib/python3.13/site-packages/django/core/handlers/exception.py", line 55, in inner
    response = get_response(request)
  File "/home/runezvdw/virtualenv/store.innovestraenterprises.co.ke/3.13/lib/python3.13/site-packages/django/utils/deprecation.py", line 119, in __call__
    response = self.process_request(request)
  File "/home/runezvdw/virtualenv/store.innovestraenterprises.co.ke/3.13/lib/python3.13/site-packages/django/middleware/common.py", line 48, in process_request
    host = request.get_host()
  File "/home/runezvdw/virtualenv/store.innovestraenterprises.co.ke/3.13/lib/python3.13/site-packages/django/http/request.py", line 202, in get_host
    raise DisallowedHost(msg)
django.core.exceptions.DisallowedHost: Invalid HTTP_HOST header: 'store.innovestraenterprises.co.ke'. You may need to add 'store.innovestraenterprises.co.ke' to ALLOWED_HOSTS.
[ERROR] [UID:2034][948592] wsgiAppHandler pApp->start_response() return NULL.
Traceback (most recent call last):
  File "/home/runezvdw/virtualenv/store.innovestraenterprises.co.ke/3.13/lib/python3.13/site-packages/django/core/handlers/exception.py", line 55, in inner
    response = get_response(request)
  File "/home/runezvdw/virtualenv/store.innovestraenterprises.co.ke/3.13/lib/python3.13/site-packages/django/core/handlers/base.py", line 181, in _get_response
    callback, callback_args, callback_kwargs = self.resolve_request(request)
                                               ~~~~~~~~~~~~~~~~~~~~^^^^^^^^^
  File "/home/runezvdw/virtualenv/store.innovestraenterprises.co.ke/3.13/lib/python3.13/site-packages/django/core/handlers/base.py", line 313, in resolve_request
    resolver_match = resolver.resolve(request.path_info)
  File "/home/runezvdw/virtualenv/store.innovestraenterprises.co.ke/3.13/lib/python3.13/site-packages/django/urls/resolvers.py", line 666, in resolve
    for pattern in self.url_patterns:
                   ^^^^^^^^^^^^^^^^^
  File "/home/runezvdw/virtualenv/store.innovestraenterprises.co.ke/3.13/lib/python3.13/site-packages/django/utils/functional.py", line 47, in __get__
    res = instance.__dict__[self.name] = self.func(instance)
                                         ~~~~~~~~~^^^^^^^^^^
  File "/home/runezvdw/virtualenv/store.innovestraenterprises.co.ke/3.13/lib/python3.13/site-packages/django/urls/resolvers.py", line 718, in url_patterns
    patterns = getattr(self.urlconf_module, "urlpatterns", self.urlconf_module)
                       ^^^^^^^^^^^^^^^^^^^
  File "/home/runezvdw/virtualenv/store.innovestraenterprises.co.ke/3.13/lib/python3.13/site-packages/django/utils/functional.py", line 47, in __get__
    res = instance.__dict__[self.name] = self.func(instance)
                                         ~~~~~~~~~^^^^^^^^^^
  File "/home/runezvdw/virtualenv/store.innovestraenterprises.co.ke/3.13/lib/python3.13/site-packages/django/urls/resolvers.py", line 711, in urlconf_module
    return import_module(self.urlconf_name)
  File "/opt/alt/python313/lib64/python3.13/importlib/__init__.py", line 88, in import_module
    return _bootstrap._gcd_import(name[level:], package, level)
           ~~~~~~~~~~~~~~~~~~~~~~^^^^^^^^^^^^^^^^^^^^^^^^^^^^^^
  File "<frozen importlib._bootstrap>", line 1387, in _gcd_import
  File "<frozen importlib._bootstrap>", line 1360, in _find_and_load
  File "<frozen importlib._bootstrap>", line 1331, in _find_and_load_unlocked
  File "<frozen importlib._bootstrap>", line 935, in _load_unlocked
  File "<frozen importlib._bootstrap_external>", line 1026, in exec_module
  File "<frozen importlib._bootstrap>", line 488, in _call_with_frames_removed
  File "/home/runezvdw/store.innovestraenterprises.co.ke/innotech/urls.py", line 9, in <module>
    path('auth/', include('Account.urls')),
                  ~~~~~~~^^^^^^^^^^^^^^^^
  File "/home/runezvdw/virtualenv/store.innovestraenterprises.co.ke/3.13/lib/python3.13/site-packages/django/urls/conf.py", line 39, in include
    urlconf_module = import_module(urlconf_module)
  File "/opt/alt/python313/lib64/python3.13/importlib/__init__.py", line 88, in import_module
    return _bootstrap._gcd_import(name[level:], package, level)
           ~~~~~~~~~~~~~~~~~~~~~~^^^^^^^^^^^^^^^^^^^^^^^^^^^^^^
  File "<frozen importlib._bootstrap>", line 1387, in _gcd_import
  File "<frozen importlib._bootstrap>", line 1360, in _find_and_load
  File "<frozen importlib._bootstrap>", line 1331, in _find_and_load_unlocked
  File "<frozen importlib._bootstrap>", line 935, in _load_unlocked
  File "<frozen importlib._bootstrap_external>", line 1026, in exec_module
  File "<frozen importlib._bootstrap>", line 488, in _call_with_frames_removed
  File "/home/runezvdw/store.innovestraenterprises.co.ke/Account/urls.py", line 2, in <module>
    from . import views
  File "/home/runezvdw/store.innovestraenterprises.co.ke/Account/views.py", line 10, in <module>
    from .models import PendingRegistration, CustomUser, PasswordReset
ImportError: cannot import name 'PendingRegistration' from 'Account.models' (/home/runezvdw/store.innovestraenterprises.co.ke/Account/models.py)

During handling of the above exception, another exception occurred:

Traceback (most recent call last):
  File "/home/runezvdw/virtualenv/store.innovestraenterprises.co.ke/3.13/lib/python3.13/site-packages/django/core/handlers/exception.py", line 55, in inner
    response = get_response(request)
  File "/home/runezvdw/virtualenv/store.innovestraenterprises.co.ke/3.13/lib/python3.13/site-packages/django/utils/deprecation.py", line 120, in __call__
    response = response or self.get_response(request)
                           ~~~~~~~~~~~~~~~~~^^^^^^^^^
  File "/home/runezvdw/virtualenv/store.innovestraenterprises.co.ke/3.13/lib/python3.13/site-packages/django/core/handlers/exception.py", line 57, in inner
    response = response_for_exception(request, exc)
  File "/home/runezvdw/virtualenv/store.innovestraenterprises.co.ke/3.13/lib/python3.13/site-packages/django/core/handlers/exception.py", line 141, in response_for_exception
    response = handle_uncaught_exception(
        request, get_resolver(get_urlconf()), sys.exc_info()
    )
  File "/home/runezvdw/virtualenv/store.innovestraenterprises.co.ke/3.13/lib/python3.13/site-packages/django/core/handlers/exception.py", line 185, in handle_uncaught_exception
    callback = resolver.resolve_error_handler(500)
  File "/home/runezvdw/virtualenv/store.innovestraenterprises.co.ke/3.13/lib/python3.13/site-packages/django/urls/resolvers.py", line 732, in resolve_error_handler
    callback = getattr(self.urlconf_module, "handler%s" % view_type, None)
                       ^^^^^^^^^^^^^^^^^^^
  File "/home/runezvdw/virtualenv/store.innovestraenterprises.co.ke/3.13/lib/python3.13/site-packages/django/utils/functional.py", line 47, in __get__
    res = instance.__dict__[self.name] = self.func(instance)
                                         ~~~~~~~~~^^^^^^^^^^
  File "/home/runezvdw/virtualenv/store.innovestraenterprises.co.ke/3.13/lib/python3.13/site-packages/django/urls/resolvers.py", line 711, in urlconf_module
    return import_module(self.urlconf_name)
  File "/opt/alt/python313/lib64/python3.13/importlib/__init__.py", line 88, in import_module
    return _bootstrap._gcd_import(name[level:], package, level)
           ~~~~~~~~~~~~~~~~~~~~~~^^^^^^^^^^^^^^^^^^^^^^^^^^^^^^
  File "<frozen importlib._bootstrap>", line 1387, in _gcd_import
  File "<frozen importlib._bootstrap>", line 1360, in _find_and_load
  File "<frozen importlib._bootstrap>", line 1331, in _find_and_load_unlocked
  File "<frozen importlib._bootstrap>", line 935, in _load_unlocked
  File "<frozen importlib._bootstrap_external>", line 1026, in exec_module
  File "<frozen importlib._bootstrap>", line 488, in _call_with_frames_removed
  File "/home/runezvdw/store.innovestraenterprises.co.ke/innotech/urls.py", line 9, in <module>
    path('auth/', include('Account.urls')),
                  ~~~~~~~^^^^^^^^^^^^^^^^
  File "/home/runezvdw/virtualenv/store.innovestraenterprises.co.ke/3.13/lib/python3.13/site-packages/django/urls/conf.py", line 39, in include
    urlconf_module = import_module(urlconf_module)
  File "/opt/alt/python313/lib64/python3.13/importlib/__init__.py", line 88, in import_module
    return _bootstrap._gcd_import(name[level:], package, level)
           ~~~~~~~~~~~~~~~~~~~~~~^^^^^^^^^^^^^^^^^^^^^^^^^^^^^^
  File "<frozen importlib._bootstrap>", line 1387, in _gcd_import
  File "<frozen importlib._bootstrap>", line 1360, in _find_and_load
  File "<frozen importlib._bootstrap>", line 1331, in _find_and_load_unlocked
  File "<frozen importlib._bootstrap>", line 935, in _load_unlocked
  File "<frozen importlib._bootstrap_external>", line 1026, in exec_module
  File "<frozen importlib._bootstrap>", line 488, in _call_with_frames_removed
  File "/home/runezvdw/store.innovestraenterprises.co.ke/Account/urls.py", line 2, in <module>
    from . import views
  File "/home/runezvdw/store.innovestraenterprises.co.ke/Account/views.py", line 10, in <module>
    from .models import PendingRegistration, CustomUser, PasswordReset
ImportError: cannot import name 'PendingRegistration' from 'Account.models' (/home/runezvdw/store.innovestraenterprises.co.ke/Account/models.py)

During handling of the above exception, another exception occurred:

Traceback (most recent call last):
  File "/home/runezvdw/virtualenv/store.innovestraenterprises.co.ke/3.13/lib/python3.13/site-packages/django/core/handlers/exception.py", line 55, in inner
    response = get_response(request)
  File "/home/runezvdw/virtualenv/store.innovestraenterprises.co.ke/3.13/lib/python3.13/site-packages/django/utils/deprecation.py", line 120, in __call__
    response = response or self.get_response(request)
                           ~~~~~~~~~~~~~~~~~^^^^^^^^^
  File "/home/runezvdw/virtualenv/store.innovestraenterprises.co.ke/3.13/lib/python3.13/site-packages/django/core/handlers/exception.py", line 57, in inner
    response = response_for_exception(request, exc)
  File "/home/runezvdw/virtualenv/store.innovestraenterprises.co.ke/3.13/lib/python3.13/site-packages/django/core/handlers/exception.py", line 141, in response_for_exception
    response = handle_uncaught_exception(
        request, get_resolver(get_urlconf()), sys.exc_info()
    )
  File "/home/runezvdw/virtualenv/store.innovestraenterprises.co.ke/3.13/lib/python3.13/site-packages/django/core/handlers/exception.py", line 185, in handle_uncaught_exception
    callback = resolver.resolve_error_handler(500)
  File "/home/runezvdw/virtualenv/store.innovestraenterprises.co.ke/3.13/lib/python3.13/site-packages/django/urls/resolvers.py", line 732, in resolve_error_handler
    callback = getattr(self.urlconf_module, "handler%s" % view_type, None)
                       ^^^^^^^^^^^^^^^^^^^
  File "/home/runezvdw/virtualenv/store.innovestraenterprises.co.ke/3.13/lib/python3.13/site-packages/django/utils/functional.py", line 47, in __get__
    res = instance.__dict__[self.name] = self.func(instance)
                                         ~~~~~~~~~^^^^^^^^^^
  File "/home/runezvdw/virtualenv/store.innovestraenterprises.co.ke/3.13/lib/python3.13/site-packages/django/urls/resolvers.py", line 711, in urlconf_module
    return import_module(self.urlconf_name)
  File "/opt/alt/python313/lib64/python3.13/importlib/__init__.py", line 88, in import_module
    return _bootstrap._gcd_import(name[level:], package, level)
           ~~~~~~~~~~~~~~~~~~~~~~^^^^^^^^^^^^^^^^^^^^^^^^^^^^^^
  File "<frozen importlib._bootstrap>", line 1387, in _gcd_import
  File "<frozen importlib._bootstrap>", line 1360, in _find_and_load
  File "<frozen importlib._bootstrap>", line 1331, in _find_and_load_unlocked
  File "<frozen importlib._bootstrap>", line 935, in _load_unlocked
  File "<frozen importlib._bootstrap_external>", line 1026, in exec_module
  File "<frozen importlib._bootstrap>", line 488, in _call_with_frames_removed
  File "/home/runezvdw/store.innovestraenterprises.co.ke/innotech/urls.py", line 9, in <module>
    path('auth/', include('Account.urls')),
                  ~~~~~~~^^^^^^^^^^^^^^^^
  File "/home/runezvdw/virtualenv/store.innovestraenterprises.co.ke/3.13/lib/python3.13/site-packages/django/urls/conf.py", line 39, in include
    urlconf_module = import_module(urlconf_module)
  File "/opt/alt/python313/lib64/python3.13/importlib/__init__.py", line 88, in import_module
    return _bootstrap._gcd_import(name[level:], package, level)
           ~~~~~~~~~~~~~~~~~~~~~~^^^^^^^^^^^^^^^^^^^^^^^^^^^^^^
  File "<frozen importlib._bootstrap>", line 1387, in _gcd_import
  File "<frozen importlib._bootstrap>", line 1360, in _find_and_load
  File "<frozen importlib._bootstrap>", line 1331, in _find_and_load_unlocked
  File "<frozen importlib._bootstrap>", line 935, in _load_unlocked
  File "<frozen importlib._bootstrap_external>", line 1026, in exec_module
  File "<frozen importlib._bootstrap>", line 488, in _call_with_frames_removed
  File "/home/runezvdw/store.innovestraenterprises.co.ke/Account/urls.py", line 2, in <module>
    from . import views
  File "/home/runezvdw/store.innovestraenterprises.co.ke/Account/views.py", line 10, in <module>
    from .models import PendingRegistration, CustomUser, PasswordReset
ImportError: cannot import name 'PendingRegistration' from 'Account.models' (/home/runezvdw/store.innovestraenterprises.co.ke/Account/models.py)

During handling of the above exception, another exception occurred:

Traceback (most recent call last):
  File "/home/runezvdw/virtualenv/store.innovestraenterprises.co.ke/3.13/lib/python3.13/site-packages/django/core/handlers/exception.py", line 55, in inner
    response = get_response(request)
  File "/home/runezvdw/virtualenv/store.innovestraenterprises.co.ke/3.13/lib/python3.13/site-packages/django/utils/deprecation.py", line 120, in __call__
    response = response or self.get_response(request)
                           ~~~~~~~~~~~~~~~~~^^^^^^^^^
  File "/home/runezvdw/virtualenv/store.innovestraenterprises.co.ke/3.13/lib/python3.13/site-packages/django/core/handlers/exception.py", line 57, in inner
    response = response_for_exception(request, exc)
  File "/home/runezvdw/virtualenv/store.innovestraenterprises.co.ke/3.13/lib/python3.13/site-packages/django/core/handlers/exception.py", line 141, in response_for_exception
    response = handle_uncaught_exception(
        request, get_resolver(get_urlconf()), sys.exc_info()
    )
  File "/home/runezvdw/virtualenv/store.innovestraenterprises.co.ke/3.13/lib/python3.13/site-packages/django/core/handlers/exception.py", line 185, in handle_uncaught_exception
    callback = resolver.resolve_error_handler(500)
  File "/home/runezvdw/virtualenv/store.innovestraenterprises.co.ke/3.13/lib/python3.13/site-packages/django/urls/resolvers.py", line 732, in resolve_error_handler
    callback = getattr(self.urlconf_module, "handler%s" % view_type, None)
                       ^^^^^^^^^^^^^^^^^^^
  File "/home/runezvdw/virtualenv/store.innovestraenterprises.co.ke/3.13/lib/python3.13/site-packages/django/utils/functional.py", line 47, in __get__
    res = instance.__dict__[self.name] = self.func(instance)
                                         ~~~~~~~~~^^^^^^^^^^
  File "/home/runezvdw/virtualenv/store.innovestraenterprises.co.ke/3.13/lib/python3.13/site-packages/django/urls/resolvers.py", line 711, in urlconf_module
    return import_module(self.urlconf_name)
  File "/opt/alt/python313/lib64/python3.13/importlib/__init__.py", line 88, in import_module
    return _bootstrap._gcd_import(name[level:], package, level)
           ~~~~~~~~~~~~~~~~~~~~~~^^^^^^^^^^^^^^^^^^^^^^^^^^^^^^
  File "<frozen importlib._bootstrap>", line 1387, in _gcd_import
  File "<frozen importlib._bootstrap>", line 1360, in _find_and_load
  File "<frozen importlib._bootstrap>", line 1331, in _find_and_load_unlocked
  File "<frozen importlib._bootstrap>", line 935, in _load_unlocked
  File "<frozen importlib._bootstrap_external>", line 1026, in exec_module
  File "<frozen importlib._bootstrap>", line 488, in _call_with_frames_removed
  File "/home/runezvdw/store.innovestraenterprises.co.ke/innotech/urls.py", line 9, in <module>
    path('auth/', include('Account.urls')),
                  ~~~~~~~^^^^^^^^^^^^^^^^
  File "/home/runezvdw/virtualenv/store.innovestraenterprises.co.ke/3.13/lib/python3.13/site-packages/django/urls/conf.py", line 39, in include
    urlconf_module = import_module(urlconf_module)
  File "/opt/alt/python313/lib64/python3.13/importlib/__init__.py", line 88, in import_module
    return _bootstrap._gcd_import(name[level:], package, level)
           ~~~~~~~~~~~~~~~~~~~~~~^^^^^^^^^^^^^^^^^^^^^^^^^^^^^^
  File "<frozen importlib._bootstrap>", line 1387, in _gcd_import
  File "<frozen importlib._bootstrap>", line 1360, in _find_and_load
  File "<frozen importlib._bootstrap>", line 1331, in _find_and_load_unlocked
  File "<frozen importlib._bootstrap>", line 935, in _load_unlocked
  File "<frozen importlib._bootstrap_external>", line 1026, in exec_module
  File "<frozen importlib._bootstrap>", line 488, in _call_with_frames_removed
  File "/home/runezvdw/store.innovestraenterprises.co.ke/Account/urls.py", line 2, in <module>
    from . import views
  File "/home/runezvdw/store.innovestraenterprises.co.ke/Account/views.py", line 10, in <module>
    from .models import PendingRegistration, CustomUser, PasswordReset
ImportError: cannot import name 'PendingRegistration' from 'Account.models' (/home/runezvdw/store.innovestraenterprises.co.ke/Account/models.py)

During handling of the above exception, another exception occurred:

Traceback (most recent call last):
  File "/home/runezvdw/virtualenv/store.innovestraenterprises.co.ke/3.13/lib/python3.13/site-packages/django/core/handlers/exception.py", line 55, in inner
    response = get_response(request)
  File "/home/runezvdw/virtualenv/store.innovestraenterprises.co.ke/3.13/lib/python3.13/site-packages/django/utils/deprecation.py", line 120, in __call__
    response = response or self.get_response(request)
                           ~~~~~~~~~~~~~~~~~^^^^^^^^^
  File "/home/runezvdw/virtualenv/store.innovestraenterprises.co.ke/3.13/lib/python3.13/site-packages/django/core/handlers/exception.py", line 57, in inner
    response = response_for_exception(request, exc)
  File "/home/runezvdw/virtualenv/store.innovestraenterprises.co.ke/3.13/lib/python3.13/site-packages/django/core/handlers/exception.py", line 141, in response_for_exception
    response = handle_uncaught_exception(
        request, get_resolver(get_urlconf()), sys.exc_info()
    )
  File "/home/runezvdw/virtualenv/store.innovestraenterprises.co.ke/3.13/lib/python3.13/site-packages/django/core/handlers/exception.py", line 185, in handle_uncaught_exception
    callback = resolver.resolve_error_handler(500)
  File "/home/runezvdw/virtualenv/store.innovestraenterprises.co.ke/3.13/lib/python3.13/site-packages/django/urls/resolvers.py", line 732, in resolve_error_handler
    callback = getattr(self.urlconf_module, "handler%s" % view_type, None)
                       ^^^^^^^^^^^^^^^^^^^
  File "/home/runezvdw/virtualenv/store.innovestraenterprises.co.ke/3.13/lib/python3.13/site-packages/django/utils/functional.py", line 47, in __get__
    res = instance.__dict__[self.name] = self.func(instance)
                                         ~~~~~~~~~^^^^^^^^^^
  File "/home/runezvdw/virtualenv/store.innovestraenterprises.co.ke/3.13/lib/python3.13/site-packages/django/urls/resolvers.py", line 711, in urlconf_module
    return import_module(self.urlconf_name)
  File "/opt/alt/python313/lib64/python3.13/importlib/__init__.py", line 88, in import_module
    return _bootstrap._gcd_import(name[level:], package, level)
           ~~~~~~~~~~~~~~~~~~~~~~^^^^^^^^^^^^^^^^^^^^^^^^^^^^^^
  File "<frozen importlib._bootstrap>", line 1387, in _gcd_import
  File "<frozen importlib._bootstrap>", line 1360, in _find_and_load
  File "<frozen importlib._bootstrap>", line 1331, in _find_and_load_unlocked
  File "<frozen importlib._bootstrap>", line 935, in _load_unlocked
  File "<frozen importlib._bootstrap_external>", line 1026, in exec_module
  File "<frozen importlib._bootstrap>", line 488, in _call_with_frames_removed
  File "/home/runezvdw/store.innovestraenterprises.co.ke/innotech/urls.py", line 9, in <module>
    path('auth/', include('Account.urls')),
                  ~~~~~~~^^^^^^^^^^^^^^^^
  File "/home/runezvdw/virtualenv/store.innovestraenterprises.co.ke/3.13/lib/python3.13/site-packages/django/urls/conf.py", line 39, in include
    urlconf_module = import_module(urlconf_module)
  File "/opt/alt/python313/lib64/python3.13/importlib/__init__.py", line 88, in import_module
    return _bootstrap._gcd_import(name[level:], package, level)
           ~~~~~~~~~~~~~~~~~~~~~~^^^^^^^^^^^^^^^^^^^^^^^^^^^^^^
  File "<frozen importlib._bootstrap>", line 1387, in _gcd_import
  File "<frozen importlib._bootstrap>", line 1360, in _find_and_load
  File "<frozen importlib._bootstrap>", line 1331, in _find_and_load_unlocked
  File "<frozen importlib._bootstrap>", line 935, in _load_unlocked
  File "<frozen importlib._bootstrap_external>", line 1026, in exec_module
  File "<frozen importlib._bootstrap>", line 488, in _call_with_frames_removed
  File "/home/runezvdw/store.innovestraenterprises.co.ke/Account/urls.py", line 2, in <module>
    from . import views
  File "/home/runezvdw/store.innovestraenterprises.co.ke/Account/views.py", line 10, in <module>
    from .models import PendingRegistration, CustomUser, PasswordReset
ImportError: cannot import name 'PendingRegistration' from 'Account.models' (/home/runezvdw/store.innovestraenterprises.co.ke/Account/models.py)

During handling of the above exception, another exception occurred:

Traceback (most recent call last):
  File "/home/runezvdw/virtualenv/store.innovestraenterprises.co.ke/3.13/lib/python3.13/site-packages/django/core/handlers/exception.py", line 55, in inner
    response = get_response(request)
  File "/home/runezvdw/virtualenv/store.innovestraenterprises.co.ke/3.13/lib/python3.13/site-packages/django/utils/deprecation.py", line 120, in __call__
    response = response or self.get_response(request)
                           ~~~~~~~~~~~~~~~~~^^^^^^^^^
  File "/home/runezvdw/virtualenv/store.innovestraenterprises.co.ke/3.13/lib/python3.13/site-packages/django/core/handlers/exception.py", line 57, in inner
    response = response_for_exception(request, exc)
  File "/home/runezvdw/virtualenv/store.innovestraenterprises.co.ke/3.13/lib/python3.13/site-packages/django/core/handlers/exception.py", line 141, in response_for_exception
    response = handle_uncaught_exception(
        request, get_resolver(get_urlconf()), sys.exc_info()
    )
  File "/home/runezvdw/virtualenv/store.innovestraenterprises.co.ke/3.13/lib/python3.13/site-packages/django/core/handlers/exception.py", line 185, in handle_uncaught_exception
    callback = resolver.resolve_error_handler(500)
  File "/home/runezvdw/virtualenv/store.innovestraenterprises.co.ke/3.13/lib/python3.13/site-packages/django/urls/resolvers.py", line 732, in resolve_error_handler
    callback = getattr(self.urlconf_module, "handler%s" % view_type, None)
                       ^^^^^^^^^^^^^^^^^^^
  File "/home/runezvdw/virtualenv/store.innovestraenterprises.co.ke/3.13/lib/python3.13/site-packages/django/utils/functional.py", line 47, in __get__
    res = instance.__dict__[self.name] = self.func(instance)
                                         ~~~~~~~~~^^^^^^^^^^
  File "/home/runezvdw/virtualenv/store.innovestraenterprises.co.ke/3.13/lib/python3.13/site-packages/django/urls/resolvers.py", line 711, in urlconf_module
    return import_module(self.urlconf_name)
  File "/opt/alt/python313/lib64/python3.13/importlib/__init__.py", line 88, in import_module
    return _bootstrap._gcd_import(name[level:], package, level)
           ~~~~~~~~~~~~~~~~~~~~~~^^^^^^^^^^^^^^^^^^^^^^^^^^^^^^
  File "<frozen importlib._bootstrap>", line 1387, in _gcd_import
  File "<frozen importlib._bootstrap>", line 1360, in _find_and_load
  File "<frozen importlib._bootstrap>", line 1331, in _find_and_load_unlocked
  File "<frozen importlib._bootstrap>", line 935, in _load_unlocked
  File "<frozen importlib._bootstrap_external>", line 1026, in exec_module
  File "<frozen importlib._bootstrap>", line 488, in _call_with_frames_removed
  File "/home/runezvdw/store.innovestraenterprises.co.ke/innotech/urls.py", line 9, in <module>
    path('auth/', include('Account.urls')),
                  ~~~~~~~^^^^^^^^^^^^^^^^
  File "/home/runezvdw/virtualenv/store.innovestraenterprises.co.ke/3.13/lib/python3.13/site-packages/django/urls/conf.py", line 39, in include
    urlconf_module = import_module(urlconf_module)
  File "/opt/alt/python313/lib64/python3.13/importlib/__init__.py", line 88, in import_module
    return _bootstrap._gcd_import(name[level:], package, level)
           ~~~~~~~~~~~~~~~~~~~~~~^^^^^^^^^^^^^^^^^^^^^^^^^^^^^^
  File "<frozen importlib._bootstrap>", line 1387, in _gcd_import
  File "<frozen importlib._bootstrap>", line 1360, in _find_and_load
  File "<frozen importlib._bootstrap>", line 1331, in _find_and_load_unlocked
  File "<frozen importlib._bootstrap>", line 935, in _load_unlocked
  File "<frozen importlib._bootstrap_external>", line 1026, in exec_module
  File "<frozen importlib._bootstrap>", line 488, in _call_with_frames_removed
  File "/home/runezvdw/store.innovestraenterprises.co.ke/Account/urls.py", line 2, in <module>
    from . import views
  File "/home/runezvdw/store.innovestraenterprises.co.ke/Account/views.py", line 10, in <module>
    from .models import PendingRegistration, CustomUser, PasswordReset
ImportError: cannot import name 'PendingRegistration' from 'Account.models' (/home/runezvdw/store.innovestraenterprises.co.ke/Account/models.py)

During handling of the above exception, another exception occurred:

Traceback (most recent call last):
  File "/home/runezvdw/virtualenv/store.innovestraenterprises.co.ke/3.13/lib/python3.13/site-packages/django/core/handlers/exception.py", line 55, in inner
    response = get_response(request)
  File "/home/runezvdw/virtualenv/store.innovestraenterprises.co.ke/3.13/lib/python3.13/site-packages/django/utils/deprecation.py", line 120, in __call__
    response = response or self.get_response(request)
                           ~~~~~~~~~~~~~~~~~^^^^^^^^^
  File "/home/runezvdw/virtualenv/store.innovestraenterprises.co.ke/3.13/lib/python3.13/site-packages/django/core/handlers/exception.py", line 57, in inner
    response = response_for_exception(request, exc)
  File "/home/runezvdw/virtualenv/store.innovestraenterprises.co.ke/3.13/lib/python3.13/site-packages/django/core/handlers/exception.py", line 141, in response_for_exception
    response = handle_uncaught_exception(
        request, get_resolver(get_urlconf()), sys.exc_info()
    )
  File "/home/runezvdw/virtualenv/store.innovestraenterprises.co.ke/3.13/lib/python3.13/site-packages/django/core/handlers/exception.py", line 185, in handle_uncaught_exception
    callback = resolver.resolve_error_handler(500)
  File "/home/runezvdw/virtualenv/store.innovestraenterprises.co.ke/3.13/lib/python3.13/site-packages/django/urls/resolvers.py", line 732, in resolve_error_handler
    callback = getattr(self.urlconf_module, "handler%s" % view_type, None)
                       ^^^^^^^^^^^^^^^^^^^
  File "/home/runezvdw/virtualenv/store.innovestraenterprises.co.ke/3.13/lib/python3.13/site-packages/django/utils/functional.py", line 47, in __get__
    res = instance.__dict__[self.name] = self.func(instance)
                                         ~~~~~~~~~^^^^^^^^^^
  File "/home/runezvdw/virtualenv/store.innovestraenterprises.co.ke/3.13/lib/python3.13/site-packages/django/urls/resolvers.py", line 711, in urlconf_module
    return import_module(self.urlconf_name)
  File "/opt/alt/python313/lib64/python3.13/importlib/__init__.py", line 88, in import_module
    return _bootstrap._gcd_import(name[level:], package, level)
           ~~~~~~~~~~~~~~~~~~~~~~^^^^^^^^^^^^^^^^^^^^^^^^^^^^^^
  File "<frozen importlib._bootstrap>", line 1387, in _gcd_import
  File "<frozen importlib._bootstrap>", line 1360, in _find_and_load
  File "<frozen importlib._bootstrap>", line 1331, in _find_and_load_unlocked
  File "<frozen importlib._bootstrap>", line 935, in _load_unlocked
  File "<frozen importlib._bootstrap_external>", line 1026, in exec_module
  File "<frozen importlib._bootstrap>", line 488, in _call_with_frames_removed
  File "/home/runezvdw/store.innovestraenterprises.co.ke/innotech/urls.py", line 9, in <module>
    path('auth/', include('Account.urls')),
                  ~~~~~~~^^^^^^^^^^^^^^^^
  File "/home/runezvdw/virtualenv/store.innovestraenterprises.co.ke/3.13/lib/python3.13/site-packages/django/urls/conf.py", line 39, in include
    urlconf_module = import_module(urlconf_module)
  File "/opt/alt/python313/lib64/python3.13/importlib/__init__.py", line 88, in import_module
    return _bootstrap._gcd_import(name[level:], package, level)
           ~~~~~~~~~~~~~~~~~~~~~~^^^^^^^^^^^^^^^^^^^^^^^^^^^^^^
  File "<frozen importlib._bootstrap>", line 1387, in _gcd_import
  File "<frozen importlib._bootstrap>", line 1360, in _find_and_load
  File "<frozen importlib._bootstrap>", line 1331, in _find_and_load_unlocked
  File "<frozen importlib._bootstrap>", line 935, in _load_unlocked
  File "<frozen importlib._bootstrap_external>", line 1026, in exec_module
  File "<frozen importlib._bootstrap>", line 488, in _call_with_frames_removed
  File "/home/runezvdw/store.innovestraenterprises.co.ke/Account/urls.py", line 2, in <module>
    from . import views
  File "/home/runezvdw/store.innovestraenterprises.co.ke/Account/views.py", line 10, in <module>
    from .models import PendingRegistration, CustomUser, PasswordReset
ImportError: cannot import name 'PendingRegistration' from 'Account.models' (/home/runezvdw/store.innovestraenterprises.co.ke/Account/models.py)

During handling of the above exception, another exception occurred:

Traceback (most recent call last):
  File "/home/runezvdw/virtualenv/store.innovestraenterprises.co.ke/3.13/lib/python3.13/site-packages/django/core/handlers/exception.py", line 55, in inner
    response = get_response(request)
  File "/home/runezvdw/virtualenv/store.innovestraenterprises.co.ke/3.13/lib/python3.13/site-packages/django/utils/deprecation.py", line 120, in __call__
    response = response or self.get_response(request)
                           ~~~~~~~~~~~~~~~~~^^^^^^^^^
  File "/home/runezvdw/virtualenv/store.innovestraenterprises.co.ke/3.13/lib/python3.13/site-packages/django/core/handlers/exception.py", line 57, in inner
    response = response_for_exception(request, exc)
  File "/home/runezvdw/virtualenv/store.innovestraenterprises.co.ke/3.13/lib/python3.13/site-packages/django/core/handlers/exception.py", line 141, in response_for_exception
    response = handle_uncaught_exception(
        request, get_resolver(get_urlconf()), sys.exc_info()
    )
  File "/home/runezvdw/virtualenv/store.innovestraenterprises.co.ke/3.13/lib/python3.13/site-packages/django/core/handlers/exception.py", line 185, in handle_uncaught_exception
    callback = resolver.resolve_error_handler(500)
  File "/home/runezvdw/virtualenv/store.innovestraenterprises.co.ke/3.13/lib/python3.13/site-packages/django/urls/resolvers.py", line 732, in resolve_error_handler
    callback = getattr(self.urlconf_module, "handler%s" % view_type, None)
                       ^^^^^^^^^^^^^^^^^^^
  File "/home/runezvdw/virtualenv/store.innovestraenterprises.co.ke/3.13/lib/python3.13/site-packages/django/utils/functional.py", line 47, in __get__
    res = instance.__dict__[self.name] = self.func(instance)
                                         ~~~~~~~~~^^^^^^^^^^
  File "/home/runezvdw/virtualenv/store.innovestraenterprises.co.ke/3.13/lib/python3.13/site-packages/django/urls/resolvers.py", line 711, in urlconf_module
    return import_module(self.urlconf_name)
  File "/opt/alt/python313/lib64/python3.13/importlib/__init__.py", line 88, in import_module
    return _bootstrap._gcd_import(name[level:], package, level)
           ~~~~~~~~~~~~~~~~~~~~~~^^^^^^^^^^^^^^^^^^^^^^^^^^^^^^
  File "<frozen importlib._bootstrap>", line 1387, in _gcd_import
  File "<frozen importlib._bootstrap>", line 1360, in _find_and_load
  File "<frozen importlib._bootstrap>", line 1331, in _find_and_load_unlocked
  File "<frozen importlib._bootstrap>", line 935, in _load_unlocked
  File "<frozen importlib._bootstrap_external>", line 1026, in exec_module
  File "<frozen importlib._bootstrap>", line 488, in _call_with_frames_removed
  File "/home/runezvdw/store.innovestraenterprises.co.ke/innotech/urls.py", line 9, in <module>
    path('auth/', include('Account.urls')),
                  ~~~~~~~^^^^^^^^^^^^^^^^
  File "/home/runezvdw/virtualenv/store.innovestraenterprises.co.ke/3.13/lib/python3.13/site-packages/django/urls/conf.py", line 39, in include
    urlconf_module = import_module(urlconf_module)
  File "/opt/alt/python313/lib64/python3.13/importlib/__init__.py", line 88, in import_module
    return _bootstrap._gcd_import(name[level:], package, level)
           ~~~~~~~~~~~~~~~~~~~~~~^^^^^^^^^^^^^^^^^^^^^^^^^^^^^^
  File "<frozen importlib._bootstrap>", line 1387, in _gcd_import
  File "<frozen importlib._bootstrap>", line 1360, in _find_and_load
  File "<frozen importlib._bootstrap>", line 1331, in _find_and_load_unlocked
  File "<frozen importlib._bootstrap>", line 935, in _load_unlocked
  File "<frozen importlib._bootstrap_external>", line 1026, in exec_module
  File "<frozen importlib._bootstrap>", line 488, in _call_with_frames_removed
  File "/home/runezvdw/store.innovestraenterprises.co.ke/Account/urls.py", line 2, in <module>
    from . import views
  File "/home/runezvdw/store.innovestraenterprises.co.ke/Account/views.py", line 10, in <module>
    from .models import PendingRegistration, CustomUser, PasswordReset
ImportError: cannot import name 'PendingRegistration' from 'Account.models' (/home/runezvdw/store.innovestraenterprises.co.ke/Account/models.py)

During handling of the above exception, another exception occurred:

Traceback (most recent call last):
  File "/home/runezvdw/virtualenv/store.innovestraenterprises.co.ke/3.13/lib/python3.13/site-packages/django/core/handlers/wsgi.py", line 124, in __call__
    response = self.get_response(request)
  File "/home/runezvdw/virtualenv/store.innovestraenterprises.co.ke/3.13/lib/python3.13/site-packages/django/core/handlers/base.py", line 140, in get_response
    response = self._middleware_chain(request)
  File "/home/runezvdw/virtualenv/store.innovestraenterprises.co.ke/3.13/lib/python3.13/site-packages/django/core/handlers/exception.py", line 57, in inner
    response = response_for_exception(request, exc)
  File "/home/runezvdw/virtualenv/store.innovestraenterprises.co.ke/3.13/lib/python3.13/site-packages/django/core/handlers/exception.py", line 141, in response_for_exception
    response = handle_uncaught_exception(
        request, get_resolver(get_urlconf()), sys.exc_info()
    )
  File "/home/runezvdw/virtualenv/store.innovestraenterprises.co.ke/3.13/lib/python3.13/site-packages/django/core/handlers/exception.py", line 185, in handle_uncaught_exception
    callback = resolver.resolve_error_handler(500)
  File "/home/runezvdw/virtualenv/store.innovestraenterprises.co.ke/3.13/lib/python3.13/site-packages/django/urls/resolvers.py", line 732, in resolve_error_handler
    callback = getattr(self.urlconf_module, "handler%s" % view_type, None)
                       ^^^^^^^^^^^^^^^^^^^
  File "/home/runezvdw/virtualenv/store.innovestraenterprises.co.ke/3.13/lib/python3.13/site-packages/django/utils/functional.py", line 47, in __get__
    res = instance.__dict__[self.name] = self.func(instance)
                                         ~~~~~~~~~^^^^^^^^^^
  File "/home/runezvdw/virtualenv/store.innovestraenterprises.co.ke/3.13/lib/python3.13/site-packages/django/urls/resolvers.py", line 711, in urlconf_module
    return import_module(self.urlconf_name)
  File "/opt/alt/python313/lib64/python3.13/importlib/__init__.py", line 88, in import_module
    return _bootstrap._gcd_import(name[level:], package, level)
           ~~~~~~~~~~~~~~~~~~~~~~^^^^^^^^^^^^^^^^^^^^^^^^^^^^^^
  File "<frozen importlib._bootstrap>", line 1387, in _gcd_import
  File "<frozen importlib._bootstrap>", line 1360, in _find_and_load
  File "<frozen importlib._bootstrap>", line 1331, in _find_and_load_unlocked
  File "<frozen importlib._bootstrap>", line 935, in _load_unlocked
  File "<frozen importlib._bootstrap_external>", line 1026, in exec_module
  File "<frozen importlib._bootstrap>", line 488, in _call_with_frames_removed
  File "/home/runezvdw/store.innovestraenterprises.co.ke/innotech/urls.py", line 9, in <module>
    path('auth/', include('Account.urls')),
                  ~~~~~~~^^^^^^^^^^^^^^^^
  File "/home/runezvdw/virtualenv/store.innovestraenterprises.co.ke/3.13/lib/python3.13/site-packages/django/urls/conf.py", line 39, in include
    urlconf_module = import_module(urlconf_module)
  File "/opt/alt/python313/lib64/python3.13/importlib/__init__.py", line 88, in import_module
    return _bootstrap._gcd_import(name[level:], package, level)
           ~~~~~~~~~~~~~~~~~~~~~~^^^^^^^^^^^^^^^^^^^^^^^^^^^^^^
  File "<frozen importlib._bootstrap>", line 1387, in _gcd_import
  File "<frozen importlib._bootstrap>", line 1360, in _find_and_load
  File "<frozen importlib._bootstrap>", line 1331, in _find_and_load_unlocked
  File "<frozen importlib._bootstrap>", line 935, in _load_unlocked
  File "<frozen importlib._bootstrap_external>", line 1026, in exec_module
  File "<frozen importlib._bootstrap>", line 488, in _call_with_frames_removed
  File "/home/runezvdw/store.innovestraenterprises.co.ke/Account/urls.py", line 2, in <module>
    from . import views
  File "/home/runezvdw/store.innovestraenterprises.co.ke/Account/views.py", line 10, in <module>
    from .models import PendingRegistration, CustomUser, PasswordReset
ImportError: cannot import name 'PendingRegistration' from 'Account.models' (/home/runezvdw/store.innovestraenterprises.co.ke/Account/models.py)
[ERROR] [UID:2034][948756] wsgiAppHandler pApp->start_response() return NULL.
Traceback (most recent call last):
  File "/home/runezvdw/virtualenv/store.innovestraenterprises.co.ke/3.13/lib/python3.13/site-packages/django/core/handlers/exception.py", line 55, in inner
    response = get_response(request)
  File "/home/runezvdw/virtualenv/store.innovestraenterprises.co.ke/3.13/lib/python3.13/site-packages/django/core/handlers/base.py", line 181, in _get_response
    callback, callback_args, callback_kwargs = self.resolve_request(request)
                                               ~~~~~~~~~~~~~~~~~~~~^^^^^^^^^
  File "/home/runezvdw/virtualenv/store.innovestraenterprises.co.ke/3.13/lib/python3.13/site-packages/django/core/handlers/base.py", line 313, in resolve_request
    resolver_match = resolver.resolve(request.path_info)
  File "/home/runezvdw/virtualenv/store.innovestraenterprises.co.ke/3.13/lib/python3.13/site-packages/django/urls/resolvers.py", line 666, in resolve
    for pattern in self.url_patterns:
                   ^^^^^^^^^^^^^^^^^
  File "/home/runezvdw/virtualenv/store.innovestraenterprises.co.ke/3.13/lib/python3.13/site-packages/django/utils/functional.py", line 47, in __get__
    res = instance.__dict__[self.name] = self.func(instance)
                                         ~~~~~~~~~^^^^^^^^^^
  File "/home/runezvdw/virtualenv/store.innovestraenterprises.co.ke/3.13/lib/python3.13/site-packages/django/urls/resolvers.py", line 718, in url_patterns
    patterns = getattr(self.urlconf_module, "urlpatterns", self.urlconf_module)
                       ^^^^^^^^^^^^^^^^^^^
  File "/home/runezvdw/virtualenv/store.innovestraenterprises.co.ke/3.13/lib/python3.13/site-packages/django/utils/functional.py", line 47, in __get__
    res = instance.__dict__[self.name] = self.func(instance)
                                         ~~~~~~~~~^^^^^^^^^^
  File "/home/runezvdw/virtualenv/store.innovestraenterprises.co.ke/3.13/lib/python3.13/site-packages/django/urls/resolvers.py", line 711, in urlconf_module
    return import_module(self.urlconf_name)
  File "/opt/alt/python313/lib64/python3.13/importlib/__init__.py", line 88, in import_module
    return _bootstrap._gcd_import(name[level:], package, level)
           ~~~~~~~~~~~~~~~~~~~~~~^^^^^^^^^^^^^^^^^^^^^^^^^^^^^^
  File "<frozen importlib._bootstrap>", line 1387, in _gcd_import
  File "<frozen importlib._bootstrap>", line 1360, in _find_and_load
  File "<frozen importlib._bootstrap>", line 1331, in _find_and_load_unlocked
  File "<frozen importlib._bootstrap>", line 935, in _load_unlocked
  File "<frozen importlib._bootstrap_external>", line 1026, in exec_module
  File "<frozen importlib._bootstrap>", line 488, in _call_with_frames_removed
  File "/home/runezvdw/store.innovestraenterprises.co.ke/innotech/urls.py", line 9, in <module>
    path('auth/', include('Account.urls')),
                  ~~~~~~~^^^^^^^^^^^^^^^^
  File "/home/runezvdw/virtualenv/store.innovestraenterprises.co.ke/3.13/lib/python3.13/site-packages/django/urls/conf.py", line 39, in include
    urlconf_module = import_module(urlconf_module)
  File "/opt/alt/python313/lib64/python3.13/importlib/__init__.py", line 88, in import_module
    return _bootstrap._gcd_import(name[level:], package, level)
           ~~~~~~~~~~~~~~~~~~~~~~^^^^^^^^^^^^^^^^^^^^^^^^^^^^^^
  File "<frozen importlib._bootstrap>", line 1387, in _gcd_import
  File "<frozen importlib._bootstrap>", line 1360, in _find_and_load
  File "<frozen importlib._bootstrap>", line 1331, in _find_and_load_unlocked
  File "<frozen importlib._bootstrap>", line 935, in _load_unlocked
  File "<frozen importlib._bootstrap_external>", line 1026, in exec_module
  File "<frozen importlib._bootstrap>", line 488, in _call_with_frames_removed
  File "/home/runezvdw/store.innovestraenterprises.co.ke/Account/urls.py", line 2, in <module>
    from . import views
  File "/home/runezvdw/store.innovestraenterprises.co.ke/Account/views.py", line 10, in <module>
    from .models import PendingRegistration, CustomUser, PasswordReset
ImportError: cannot import name 'PendingRegistration' from 'Account.models' (/home/runezvdw/store.innovestraenterprises.co.ke/Account/models.py)

During handling of the above exception, another exception occurred:

Traceback (most recent call last):
  File "/home/runezvdw/virtualenv/store.innovestraenterprises.co.ke/3.13/lib/python3.13/site-packages/django/core/handlers/exception.py", line 55, in inner
    response = get_response(request)
  File "/home/runezvdw/virtualenv/store.innovestraenterprises.co.ke/3.13/lib/python3.13/site-packages/django/utils/deprecation.py", line 120, in __call__
    response = response or self.get_response(request)
                           ~~~~~~~~~~~~~~~~~^^^^^^^^^
  File "/home/runezvdw/virtualenv/store.innovestraenterprises.co.ke/3.13/lib/python3.13/site-packages/django/core/handlers/exception.py", line 57, in inner
    response = response_for_exception(request, exc)
  File "/home/runezvdw/virtualenv/store.innovestraenterprises.co.ke/3.13/lib/python3.13/site-packages/django/core/handlers/exception.py", line 141, in response_for_exception
    response = handle_uncaught_exception(
        request, get_resolver(get_urlconf()), sys.exc_info()
    )
  File "/home/runezvdw/virtualenv/store.innovestraenterprises.co.ke/3.13/lib/python3.13/site-packages/django/core/handlers/exception.py", line 185, in handle_uncaught_exception
    callback = resolver.resolve_error_handler(500)
  File "/home/runezvdw/virtualenv/store.innovestraenterprises.co.ke/3.13/lib/python3.13/site-packages/django/urls/resolvers.py", line 732, in resolve_error_handler
    callback = getattr(self.urlconf_module, "handler%s" % view_type, None)
                       ^^^^^^^^^^^^^^^^^^^
  File "/home/runezvdw/virtualenv/store.innovestraenterprises.co.ke/3.13/lib/python3.13/site-packages/django/utils/functional.py", line 47, in __get__
    res = instance.__dict__[self.name] = self.func(instance)
                                         ~~~~~~~~~^^^^^^^^^^
  File "/home/runezvdw/virtualenv/store.innovestraenterprises.co.ke/3.13/lib/python3.13/site-packages/django/urls/resolvers.py", line 711, in urlconf_module
    return import_module(self.urlconf_name)
  File "/opt/alt/python313/lib64/python3.13/importlib/__init__.py", line 88, in import_module
    return _bootstrap._gcd_import(name[level:], package, level)
           ~~~~~~~~~~~~~~~~~~~~~~^^^^^^^^^^^^^^^^^^^^^^^^^^^^^^
  File "<frozen importlib._bootstrap>", line 1387, in _gcd_import
  File "<frozen importlib._bootstrap>", line 1360, in _find_and_load
  File "<frozen importlib._bootstrap>", line 1331, in _find_and_load_unlocked
  File "<frozen importlib._bootstrap>", line 935, in _load_unlocked
  File "<frozen importlib._bootstrap_external>", line 1026, in exec_module
  File "<frozen importlib._bootstrap>", line 488, in _call_with_frames_removed
  File "/home/runezvdw/store.innovestraenterprises.co.ke/innotech/urls.py", line 9, in <module>
    path('auth/', include('Account.urls')),
                  ~~~~~~~^^^^^^^^^^^^^^^^
  File "/home/runezvdw/virtualenv/store.innovestraenterprises.co.ke/3.13/lib/python3.13/site-packages/django/urls/conf.py", line 39, in include
    urlconf_module = import_module(urlconf_module)
  File "/opt/alt/python313/lib64/python3.13/importlib/__init__.py", line 88, in import_module
    return _bootstrap._gcd_import(name[level:], package, level)
           ~~~~~~~~~~~~~~~~~~~~~~^^^^^^^^^^^^^^^^^^^^^^^^^^^^^^
  File "<frozen importlib._bootstrap>", line 1387, in _gcd_import
  File "<frozen importlib._bootstrap>", line 1360, in _find_and_load
  File "<frozen importlib._bootstrap>", line 1331, in _find_and_load_unlocked
  File "<frozen importlib._bootstrap>", line 935, in _load_unlocked
  File "<frozen importlib._bootstrap_external>", line 1026, in exec_module
  File "<frozen importlib._bootstrap>", line 488, in _call_with_frames_removed
  File "/home/runezvdw/store.innovestraenterprises.co.ke/Account/urls.py", line 2, in <module>
    from . import views
  File "/home/runezvdw/store.innovestraenterprises.co.ke/Account/views.py", line 10, in <module>
    from .models import PendingRegistration, CustomUser, PasswordReset
ImportError: cannot import name 'PendingRegistration' from 'Account.models' (/home/runezvdw/store.innovestraenterprises.co.ke/Account/models.py)

During handling of the above exception, another exception occurred:

Traceback (most recent call last):
  File "/home/runezvdw/virtualenv/store.innovestraenterprises.co.ke/3.13/lib/python3.13/site-packages/django/core/handlers/exception.py", line 55, in inner
    response = get_response(request)
  File "/home/runezvdw/virtualenv/store.innovestraenterprises.co.ke/3.13/lib/python3.13/site-packages/django/utils/deprecation.py", line 120, in __call__
    response = response or self.get_response(request)
                           ~~~~~~~~~~~~~~~~~^^^^^^^^^
  File "/home/runezvdw/virtualenv/store.innovestraenterprises.co.ke/3.13/lib/python3.13/site-packages/django/core/handlers/exception.py", line 57, in inner
    response = response_for_exception(request, exc)
  File "/home/runezvdw/virtualenv/store.innovestraenterprises.co.ke/3.13/lib/python3.13/site-packages/django/core/handlers/exception.py", line 141, in response_for_exception
    response = handle_uncaught_exception(
        request, get_resolver(get_urlconf()), sys.exc_info()
    )
  File "/home/runezvdw/virtualenv/store.innovestraenterprises.co.ke/3.13/lib/python3.13/site-packages/django/core/handlers/exception.py", line 185, in handle_uncaught_exception
    callback = resolver.resolve_error_handler(500)
  File "/home/runezvdw/virtualenv/store.innovestraenterprises.co.ke/3.13/lib/python3.13/site-packages/django/urls/resolvers.py", line 732, in resolve_error_handler
    callback = getattr(self.urlconf_module, "handler%s" % view_type, None)
                       ^^^^^^^^^^^^^^^^^^^
  File "/home/runezvdw/virtualenv/store.innovestraenterprises.co.ke/3.13/lib/python3.13/site-packages/django/utils/functional.py", line 47, in __get__
    res = instance.__dict__[self.name] = self.func(instance)
                                         ~~~~~~~~~^^^^^^^^^^
  File "/home/runezvdw/virtualenv/store.innovestraenterprises.co.ke/3.13/lib/python3.13/site-packages/django/urls/resolvers.py", line 711, in urlconf_module
    return import_module(self.urlconf_name)
  File "/opt/alt/python313/lib64/python3.13/importlib/__init__.py", line 88, in import_module
    return _bootstrap._gcd_import(name[level:], package, level)
           ~~~~~~~~~~~~~~~~~~~~~~^^^^^^^^^^^^^^^^^^^^^^^^^^^^^^
  File "<frozen importlib._bootstrap>", line 1387, in _gcd_import
  File "<frozen importlib._bootstrap>", line 1360, in _find_and_load
  File "<frozen importlib._bootstrap>", line 1331, in _find_and_load_unlocked
  File "<frozen importlib._bootstrap>", line 935, in _load_unlocked
  File "<frozen importlib._bootstrap_external>", line 1026, in exec_module
  File "<frozen importlib._bootstrap>", line 488, in _call_with_frames_removed
  File "/home/runezvdw/store.innovestraenterprises.co.ke/innotech/urls.py", line 9, in <module>
    path('auth/', include('Account.urls')),
                  ~~~~~~~^^^^^^^^^^^^^^^^
  File "/home/runezvdw/virtualenv/store.innovestraenterprises.co.ke/3.13/lib/python3.13/site-packages/django/urls/conf.py", line 39, in include
    urlconf_module = import_module(urlconf_module)
  File "/opt/alt/python313/lib64/python3.13/importlib/__init__.py", line 88, in import_module
    return _bootstrap._gcd_import(name[level:], package, level)
           ~~~~~~~~~~~~~~~~~~~~~~^^^^^^^^^^^^^^^^^^^^^^^^^^^^^^
  File "<frozen importlib._bootstrap>", line 1387, in _gcd_import
  File "<frozen importlib._bootstrap>", line 1360, in _find_and_load
  File "<frozen importlib._bootstrap>", line 1331, in _find_and_load_unlocked
  File "<frozen importlib._bootstrap>", line 935, in _load_unlocked
  File "<frozen importlib._bootstrap_external>", line 1026, in exec_module
  File "<frozen importlib._bootstrap>", line 488, in _call_with_frames_removed
  File "/home/runezvdw/store.innovestraenterprises.co.ke/Account/urls.py", line 2, in <module>
    from . import views
  File "/home/runezvdw/store.innovestraenterprises.co.ke/Account/views.py", line 10, in <module>
    from .models import PendingRegistration, CustomUser, PasswordReset
ImportError: cannot import name 'PendingRegistration' from 'Account.models' (/home/runezvdw/store.innovestraenterprises.co.ke/Account/models.py)

During handling of the above exception, another exception occurred:

Traceback (most recent call last):
  File "/home/runezvdw/virtualenv/store.innovestraenterprises.co.ke/3.13/lib/python3.13/site-packages/django/core/handlers/exception.py", line 55, in inner
    response = get_response(request)
  File "/home/runezvdw/virtualenv/store.innovestraenterprises.co.ke/3.13/lib/python3.13/site-packages/django/utils/deprecation.py", line 120, in __call__
    response = response or self.get_response(request)
                           ~~~~~~~~~~~~~~~~~^^^^^^^^^
  File "/home/runezvdw/virtualenv/store.innovestraenterprises.co.ke/3.13/lib/python3.13/site-packages/django/core/handlers/exception.py", line 57, in inner
    response = response_for_exception(request, exc)
  File "/home/runezvdw/virtualenv/store.innovestraenterprises.co.ke/3.13/lib/python3.13/site-packages/django/core/handlers/exception.py", line 141, in response_for_exception
    response = handle_uncaught_exception(
        request, get_resolver(get_urlconf()), sys.exc_info()
    )
  File "/home/runezvdw/virtualenv/store.innovestraenterprises.co.ke/3.13/lib/python3.13/site-packages/django/core/handlers/exception.py", line 185, in handle_uncaught_exception
    callback = resolver.resolve_error_handler(500)
  File "/home/runezvdw/virtualenv/store.innovestraenterprises.co.ke/3.13/lib/python3.13/site-packages/django/urls/resolvers.py", line 732, in resolve_error_handler
    callback = getattr(self.urlconf_module, "handler%s" % view_type, None)
                       ^^^^^^^^^^^^^^^^^^^
  File "/home/runezvdw/virtualenv/store.innovestraenterprises.co.ke/3.13/lib/python3.13/site-packages/django/utils/functional.py", line 47, in __get__
    res = instance.__dict__[self.name] = self.func(instance)
                                         ~~~~~~~~~^^^^^^^^^^
  File "/home/runezvdw/virtualenv/store.innovestraenterprises.co.ke/3.13/lib/python3.13/site-packages/django/urls/resolvers.py", line 711, in urlconf_module
    return import_module(self.urlconf_name)
  File "/opt/alt/python313/lib64/python3.13/importlib/__init__.py", line 88, in import_module
    return _bootstrap._gcd_import(name[level:], package, level)
           ~~~~~~~~~~~~~~~~~~~~~~^^^^^^^^^^^^^^^^^^^^^^^^^^^^^^
  File "<frozen importlib._bootstrap>", line 1387, in _gcd_import
  File "<frozen importlib._bootstrap>", line 1360, in _find_and_load
  File "<frozen importlib._bootstrap>", line 1331, in _find_and_load_unlocked
  File "<frozen importlib._bootstrap>", line 935, in _load_unlocked
  File "<frozen importlib._bootstrap_external>", line 1026, in exec_module
  File "<frozen importlib._bootstrap>", line 488, in _call_with_frames_removed
  File "/home/runezvdw/store.innovestraenterprises.co.ke/innotech/urls.py", line 9, in <module>
    path('auth/', include('Account.urls')),
                  ~~~~~~~^^^^^^^^^^^^^^^^
  File "/home/runezvdw/virtualenv/store.innovestraenterprises.co.ke/3.13/lib/python3.13/site-packages/django/urls/conf.py", line 39, in include
    urlconf_module = import_module(urlconf_module)
  File "/opt/alt/python313/lib64/python3.13/importlib/__init__.py", line 88, in import_module
    return _bootstrap._gcd_import(name[level:], package, level)
           ~~~~~~~~~~~~~~~~~~~~~~^^^^^^^^^^^^^^^^^^^^^^^^^^^^^^
  File "<frozen importlib._bootstrap>", line 1387, in _gcd_import
  File "<frozen importlib._bootstrap>", line 1360, in _find_and_load
  File "<frozen importlib._bootstrap>", line 1331, in _find_and_load_unlocked
  File "<frozen importlib._bootstrap>", line 935, in _load_unlocked
  File "<frozen importlib._bootstrap_external>", line 1026, in exec_module
  File "<frozen importlib._bootstrap>", line 488, in _call_with_frames_removed
  File "/home/runezvdw/store.innovestraenterprises.co.ke/Account/urls.py", line 2, in <module>
    from . import views
  File "/home/runezvdw/store.innovestraenterprises.co.ke/Account/views.py", line 10, in <module>
    from .models import PendingRegistration, CustomUser, PasswordReset
ImportError: cannot import name 'PendingRegistration' from 'Account.models' (/home/runezvdw/store.innovestraenterprises.co.ke/Account/models.py)

During handling of the above exception, another exception occurred:

Traceback (most recent call last):
  File "/home/runezvdw/virtualenv/store.innovestraenterprises.co.ke/3.13/lib/python3.13/site-packages/django/core/handlers/exception.py", line 55, in inner
    response = get_response(request)
  File "/home/runezvdw/virtualenv/store.innovestraenterprises.co.ke/3.13/lib/python3.13/site-packages/django/utils/deprecation.py", line 120, in __call__
    response = response or self.get_response(request)
                           ~~~~~~~~~~~~~~~~~^^^^^^^^^
  File "/home/runezvdw/virtualenv/store.innovestraenterprises.co.ke/3.13/lib/python3.13/site-packages/django/core/handlers/exception.py", line 57, in inner
    response = response_for_exception(request, exc)
  File "/home/runezvdw/virtualenv/store.innovestraenterprises.co.ke/3.13/lib/python3.13/site-packages/django/core/handlers/exception.py", line 141, in response_for_exception
    response = handle_uncaught_exception(
        request, get_resolver(get_urlconf()), sys.exc_info()
    )
  File "/home/runezvdw/virtualenv/store.innovestraenterprises.co.ke/3.13/lib/python3.13/site-packages/django/core/handlers/exception.py", line 185, in handle_uncaught_exception
    callback = resolver.resolve_error_handler(500)
  File "/home/runezvdw/virtualenv/store.innovestraenterprises.co.ke/3.13/lib/python3.13/site-packages/django/urls/resolvers.py", line 732, in resolve_error_handler
    callback = getattr(self.urlconf_module, "handler%s" % view_type, None)
                       ^^^^^^^^^^^^^^^^^^^
  File "/home/runezvdw/virtualenv/store.innovestraenterprises.co.ke/3.13/lib/python3.13/site-packages/django/utils/functional.py", line 47, in __get__
    res = instance.__dict__[self.name] = self.func(instance)
                                         ~~~~~~~~~^^^^^^^^^^
  File "/home/runezvdw/virtualenv/store.innovestraenterprises.co.ke/3.13/lib/python3.13/site-packages/django/urls/resolvers.py", line 711, in urlconf_module
    return import_module(self.urlconf_name)
  File "/opt/alt/python313/lib64/python3.13/importlib/__init__.py", line 88, in import_module
    return _bootstrap._gcd_import(name[level:], package, level)
           ~~~~~~~~~~~~~~~~~~~~~~^^^^^^^^^^^^^^^^^^^^^^^^^^^^^^
  File "<frozen importlib._bootstrap>", line 1387, in _gcd_import
  File "<frozen importlib._bootstrap>", line 1360, in _find_and_load
  File "<frozen importlib._bootstrap>", line 1331, in _find_and_load_unlocked
  File "<frozen importlib._bootstrap>", line 935, in _load_unlocked
  File "<frozen importlib._bootstrap_external>", line 1026, in exec_module
  File "<frozen importlib._bootstrap>", line 488, in _call_with_frames_removed
  File "/home/runezvdw/store.innovestraenterprises.co.ke/innotech/urls.py", line 9, in <module>
    path('auth/', include('Account.urls')),
                  ~~~~~~~^^^^^^^^^^^^^^^^
  File "/home/runezvdw/virtualenv/store.innovestraenterprises.co.ke/3.13/lib/python3.13/site-packages/django/urls/conf.py", line 39, in include
    urlconf_module = import_module(urlconf_module)
  File "/opt/alt/python313/lib64/python3.13/importlib/__init__.py", line 88, in import_module
    return _bootstrap._gcd_import(name[level:], package, level)
           ~~~~~~~~~~~~~~~~~~~~~~^^^^^^^^^^^^^^^^^^^^^^^^^^^^^^
  File "<frozen importlib._bootstrap>", line 1387, in _gcd_import
  File "<frozen importlib._bootstrap>", line 1360, in _find_and_load
  File "<frozen importlib._bootstrap>", line 1331, in _find_and_load_unlocked
  File "<frozen importlib._bootstrap>", line 935, in _load_unlocked
  File "<frozen importlib._bootstrap_external>", line 1026, in exec_module
  File "<frozen importlib._bootstrap>", line 488, in _call_with_frames_removed
  File "/home/runezvdw/store.innovestraenterprises.co.ke/Account/urls.py", line 2, in <module>
    from . import views
  File "/home/runezvdw/store.innovestraenterprises.co.ke/Account/views.py", line 10, in <module>
    from .models import PendingRegistration, CustomUser, PasswordReset
ImportError: cannot import name 'PendingRegistration' from 'Account.models' (/home/runezvdw/store.innovestraenterprises.co.ke/Account/models.py)

During handling of the above exception, another exception occurred:

Traceback (most recent call last):
  File "/home/runezvdw/virtualenv/store.innovestraenterprises.co.ke/3.13/lib/python3.13/site-packages/django/core/handlers/exception.py", line 55, in inner
    response = get_response(request)
  File "/home/runezvdw/virtualenv/store.innovestraenterprises.co.ke/3.13/lib/python3.13/site-packages/django/utils/deprecation.py", line 120, in __call__
    response = response or self.get_response(request)
                           ~~~~~~~~~~~~~~~~~^^^^^^^^^
  File "/home/runezvdw/virtualenv/store.innovestraenterprises.co.ke/3.13/lib/python3.13/site-packages/django/core/handlers/exception.py", line 57, in inner
    response = response_for_exception(request, exc)
  File "/home/runezvdw/virtualenv/store.innovestraenterprises.co.ke/3.13/lib/python3.13/site-packages/django/core/handlers/exception.py", line 141, in response_for_exception
    response = handle_uncaught_exception(
        request, get_resolver(get_urlconf()), sys.exc_info()
    )
  File "/home/runezvdw/virtualenv/store.innovestraenterprises.co.ke/3.13/lib/python3.13/site-packages/django/core/handlers/exception.py", line 185, in handle_uncaught_exception
    callback = resolver.resolve_error_handler(500)
  File "/home/runezvdw/virtualenv/store.innovestraenterprises.co.ke/3.13/lib/python3.13/site-packages/django/urls/resolvers.py", line 732, in resolve_error_handler
    callback = getattr(self.urlconf_module, "handler%s" % view_type, None)
                       ^^^^^^^^^^^^^^^^^^^
  File "/home/runezvdw/virtualenv/store.innovestraenterprises.co.ke/3.13/lib/python3.13/site-packages/django/utils/functional.py", line 47, in __get__
    res = instance.__dict__[self.name] = self.func(instance)
                                         ~~~~~~~~~^^^^^^^^^^
  File "/home/runezvdw/virtualenv/store.innovestraenterprises.co.ke/3.13/lib/python3.13/site-packages/django/urls/resolvers.py", line 711, in urlconf_module
    return import_module(self.urlconf_name)
  File "/opt/alt/python313/lib64/python3.13/importlib/__init__.py", line 88, in import_module
    return _bootstrap._gcd_import(name[level:], package, level)
           ~~~~~~~~~~~~~~~~~~~~~~^^^^^^^^^^^^^^^^^^^^^^^^^^^^^^
  File "<frozen importlib._bootstrap>", line 1387, in _gcd_import
  File "<frozen importlib._bootstrap>", line 1360, in _find_and_load
  File "<frozen importlib._bootstrap>", line 1331, in _find_and_load_unlocked
  File "<frozen importlib._bootstrap>", line 935, in _load_unlocked
  File "<frozen importlib._bootstrap_external>", line 1026, in exec_module
  File "<frozen importlib._bootstrap>", line 488, in _call_with_frames_removed
  File "/home/runezvdw/store.innovestraenterprises.co.ke/innotech/urls.py", line 9, in <module>
    path('auth/', include('Account.urls')),
                  ~~~~~~~^^^^^^^^^^^^^^^^
  File "/home/runezvdw/virtualenv/store.innovestraenterprises.co.ke/3.13/lib/python3.13/site-packages/django/urls/conf.py", line 39, in include
    urlconf_module = import_module(urlconf_module)
  File "/opt/alt/python313/lib64/python3.13/importlib/__init__.py", line 88, in import_module
    return _bootstrap._gcd_import(name[level:], package, level)
           ~~~~~~~~~~~~~~~~~~~~~~^^^^^^^^^^^^^^^^^^^^^^^^^^^^^^
  File "<frozen importlib._bootstrap>", line 1387, in _gcd_import
  File "<frozen importlib._bootstrap>", line 1360, in _find_and_load
  File "<frozen importlib._bootstrap>", line 1331, in _find_and_load_unlocked
  File "<frozen importlib._bootstrap>", line 935, in _load_unlocked
  File "<frozen importlib._bootstrap_external>", line 1026, in exec_module
  File "<frozen importlib._bootstrap>", line 488, in _call_with_frames_removed
  File "/home/runezvdw/store.innovestraenterprises.co.ke/Account/urls.py", line 2, in <module>
    from . import views
  File "/home/runezvdw/store.innovestraenterprises.co.ke/Account/views.py", line 10, in <module>
    from .models import PendingRegistration, CustomUser, PasswordReset
ImportError: cannot import name 'PendingRegistration' from 'Account.models' (/home/runezvdw/store.innovestraenterprises.co.ke/Account/models.py)

During handling of the above exception, another exception occurred:

Traceback (most recent call last):
  File "/home/runezvdw/virtualenv/store.innovestraenterprises.co.ke/3.13/lib/python3.13/site-packages/django/core/handlers/exception.py", line 55, in inner
    response = get_response(request)
  File "/home/runezvdw/virtualenv/store.innovestraenterprises.co.ke/3.13/lib/python3.13/site-packages/django/utils/deprecation.py", line 120, in __call__
    response = response or self.get_response(request)
                           ~~~~~~~~~~~~~~~~~^^^^^^^^^
  File "/home/runezvdw/virtualenv/store.innovestraenterprises.co.ke/3.13/lib/python3.13/site-packages/django/core/handlers/exception.py", line 57, in inner
    response = response_for_exception(request, exc)
  File "/home/runezvdw/virtualenv/store.innovestraenterprises.co.ke/3.13/lib/python3.13/site-packages/django/core/handlers/exception.py", line 141, in response_for_exception
    response = handle_uncaught_exception(
        request, get_resolver(get_urlconf()), sys.exc_info()
    )
  File "/home/runezvdw/virtualenv/store.innovestraenterprises.co.ke/3.13/lib/python3.13/site-packages/django/core/handlers/exception.py", line 185, in handle_uncaught_exception
    callback = resolver.resolve_error_handler(500)
  File "/home/runezvdw/virtualenv/store.innovestraenterprises.co.ke/3.13/lib/python3.13/site-packages/django/urls/resolvers.py", line 732, in resolve_error_handler
    callback = getattr(self.urlconf_module, "handler%s" % view_type, None)
                       ^^^^^^^^^^^^^^^^^^^
  File "/home/runezvdw/virtualenv/store.innovestraenterprises.co.ke/3.13/lib/python3.13/site-packages/django/utils/functional.py", line 47, in __get__
    res = instance.__dict__[self.name] = self.func(instance)
                                         ~~~~~~~~~^^^^^^^^^^
  File "/home/runezvdw/virtualenv/store.innovestraenterprises.co.ke/3.13/lib/python3.13/site-packages/django/urls/resolvers.py", line 711, in urlconf_module
    return import_module(self.urlconf_name)
  File "/opt/alt/python313/lib64/python3.13/importlib/__init__.py", line 88, in import_module
    return _bootstrap._gcd_import(name[level:], package, level)
           ~~~~~~~~~~~~~~~~~~~~~~^^^^^^^^^^^^^^^^^^^^^^^^^^^^^^
  File "<frozen importlib._bootstrap>", line 1387, in _gcd_import
  File "<frozen importlib._bootstrap>", line 1360, in _find_and_load
  File "<frozen importlib._bootstrap>", line 1331, in _find_and_load_unlocked
  File "<frozen importlib._bootstrap>", line 935, in _load_unlocked
  File "<frozen importlib._bootstrap_external>", line 1026, in exec_module
  File "<frozen importlib._bootstrap>", line 488, in _call_with_frames_removed
  File "/home/runezvdw/store.innovestraenterprises.co.ke/innotech/urls.py", line 9, in <module>
    path('auth/', include('Account.urls')),
                  ~~~~~~~^^^^^^^^^^^^^^^^
  File "/home/runezvdw/virtualenv/store.innovestraenterprises.co.ke/3.13/lib/python3.13/site-packages/django/urls/conf.py", line 39, in include
    urlconf_module = import_module(urlconf_module)
  File "/opt/alt/python313/lib64/python3.13/importlib/__init__.py", line 88, in import_module
    return _bootstrap._gcd_import(name[level:], package, level)
           ~~~~~~~~~~~~~~~~~~~~~~^^^^^^^^^^^^^^^^^^^^^^^^^^^^^^
  File "<frozen importlib._bootstrap>", line 1387, in _gcd_import
  File "<frozen importlib._bootstrap>", line 1360, in _find_and_load
  File "<frozen importlib._bootstrap>", line 1331, in _find_and_load_unlocked
  File "<frozen importlib._bootstrap>", line 935, in _load_unlocked
  File "<frozen importlib._bootstrap_external>", line 1026, in exec_module
  File "<frozen importlib._bootstrap>", line 488, in _call_with_frames_removed
  File "/home/runezvdw/store.innovestraenterprises.co.ke/Account/urls.py", line 2, in <module>
    from . import views
  File "/home/runezvdw/store.innovestraenterprises.co.ke/Account/views.py", line 10, in <module>
    from .models import PendingRegistration, CustomUser, PasswordReset
ImportError: cannot import name 'PendingRegistration' from 'Account.models' (/home/runezvdw/store.innovestraenterprises.co.ke/Account/models.py)

During handling of the above exception, another exception occurred:

Traceback (most recent call last):
  File "/home/runezvdw/virtualenv/store.innovestraenterprises.co.ke/3.13/lib/python3.13/site-packages/django/core/handlers/exception.py", line 55, in inner
    response = get_response(request)
  File "/home/runezvdw/virtualenv/store.innovestraenterprises.co.ke/3.13/lib/python3.13/site-packages/django/utils/deprecation.py", line 120, in __call__
    response = response or self.get_response(request)
                           ~~~~~~~~~~~~~~~~~^^^^^^^^^
  File "/home/runezvdw/virtualenv/store.innovestraenterprises.co.ke/3.13/lib/python3.13/site-packages/django/core/handlers/exception.py", line 57, in inner
    response = response_for_exception(request, exc)
  File "/home/runezvdw/virtualenv/store.innovestraenterprises.co.ke/3.13/lib/python3.13/site-packages/django/core/handlers/exception.py", line 141, in response_for_exception
    response = handle_uncaught_exception(
        request, get_resolver(get_urlconf()), sys.exc_info()
    )
  File "/home/runezvdw/virtualenv/store.innovestraenterprises.co.ke/3.13/lib/python3.13/site-packages/django/core/handlers/exception.py", line 185, in handle_uncaught_exception
    callback = resolver.resolve_error_handler(500)
  File "/home/runezvdw/virtualenv/store.innovestraenterprises.co.ke/3.13/lib/python3.13/site-packages/django/urls/resolvers.py", line 732, in resolve_error_handler
    callback = getattr(self.urlconf_module, "handler%s" % view_type, None)
                       ^^^^^^^^^^^^^^^^^^^
  File "/home/runezvdw/virtualenv/store.innovestraenterprises.co.ke/3.13/lib/python3.13/site-packages/django/utils/functional.py", line 47, in __get__
    res = instance.__dict__[self.name] = self.func(instance)
                                         ~~~~~~~~~^^^^^^^^^^
  File "/home/runezvdw/virtualenv/store.innovestraenterprises.co.ke/3.13/lib/python3.13/site-packages/django/urls/resolvers.py", line 711, in urlconf_module
    return import_module(self.urlconf_name)
  File "/opt/alt/python313/lib64/python3.13/importlib/__init__.py", line 88, in import_module
    return _bootstrap._gcd_import(name[level:], package, level)
           ~~~~~~~~~~~~~~~~~~~~~~^^^^^^^^^^^^^^^^^^^^^^^^^^^^^^
  File "<frozen importlib._bootstrap>", line 1387, in _gcd_import
  File "<frozen importlib._bootstrap>", line 1360, in _find_and_load
  File "<frozen importlib._bootstrap>", line 1331, in _find_and_load_unlocked
  File "<frozen importlib._bootstrap>", line 935, in _load_unlocked
  File "<frozen importlib._bootstrap_external>", line 1026, in exec_module
  File "<frozen importlib._bootstrap>", line 488, in _call_with_frames_removed
  File "/home/runezvdw/store.innovestraenterprises.co.ke/innotech/urls.py", line 9, in <module>
    path('auth/', include('Account.urls')),
                  ~~~~~~~^^^^^^^^^^^^^^^^
  File "/home/runezvdw/virtualenv/store.innovestraenterprises.co.ke/3.13/lib/python3.13/site-packages/django/urls/conf.py", line 39, in include
    urlconf_module = import_module(urlconf_module)
  File "/opt/alt/python313/lib64/python3.13/importlib/__init__.py", line 88, in import_module
    return _bootstrap._gcd_import(name[level:], package, level)
           ~~~~~~~~~~~~~~~~~~~~~~^^^^^^^^^^^^^^^^^^^^^^^^^^^^^^
  File "<frozen importlib._bootstrap>", line 1387, in _gcd_import
  File "<frozen importlib._bootstrap>", line 1360, in _find_and_load
  File "<frozen importlib._bootstrap>", line 1331, in _find_and_load_unlocked
  File "<frozen importlib._bootstrap>", line 935, in _load_unlocked
  File "<frozen importlib._bootstrap_external>", line 1026, in exec_module
  File "<frozen importlib._bootstrap>", line 488, in _call_with_frames_removed
  File "/home/runezvdw/store.innovestraenterprises.co.ke/Account/urls.py", line 2, in <module>
    from . import views
  File "/home/runezvdw/store.innovestraenterprises.co.ke/Account/views.py", line 10, in <module>
    from .models import PendingRegistration, CustomUser, PasswordReset
ImportError: cannot import name 'PendingRegistration' from 'Account.models' (/home/runezvdw/store.innovestraenterprises.co.ke/Account/models.py)

During handling of the above exception, another exception occurred:

Traceback (most recent call last):
  File "/home/runezvdw/virtualenv/store.innovestraenterprises.co.ke/3.13/lib/python3.13/site-packages/django/core/handlers/wsgi.py", line 124, in __call__
    response = self.get_response(request)
  File "/home/runezvdw/virtualenv/store.innovestraenterprises.co.ke/3.13/lib/python3.13/site-packages/django/core/handlers/base.py", line 140, in get_response
    response = self._middleware_chain(request)
  File "/home/runezvdw/virtualenv/store.innovestraenterprises.co.ke/3.13/lib/python3.13/site-packages/django/core/handlers/exception.py", line 57, in inner
    response = response_for_exception(request, exc)
  File "/home/runezvdw/virtualenv/store.innovestraenterprises.co.ke/3.13/lib/python3.13/site-packages/django/core/handlers/exception.py", line 141, in response_for_exception
    response = handle_uncaught_exception(
        request, get_resolver(get_urlconf()), sys.exc_info()
    )
  File "/home/runezvdw/virtualenv/store.innovestraenterprises.co.ke/3.13/lib/python3.13/site-packages/django/core/handlers/exception.py", line 185, in handle_uncaught_exception
    callback = resolver.resolve_error_handler(500)
  File "/home/runezvdw/virtualenv/store.innovestraenterprises.co.ke/3.13/lib/python3.13/site-packages/django/urls/resolvers.py", line 732, in resolve_error_handler
    callback = getattr(self.urlconf_module, "handler%s" % view_type, None)
                       ^^^^^^^^^^^^^^^^^^^
  File "/home/runezvdw/virtualenv/store.innovestraenterprises.co.ke/3.13/lib/python3.13/site-packages/django/utils/functional.py", line 47, in __get__
    res = instance.__dict__[self.name] = self.func(instance)
                                         ~~~~~~~~~^^^^^^^^^^
  File "/home/runezvdw/virtualenv/store.innovestraenterprises.co.ke/3.13/lib/python3.13/site-packages/django/urls/resolvers.py", line 711, in urlconf_module
    return import_module(self.urlconf_name)
  File "/opt/alt/python313/lib64/python3.13/importlib/__init__.py", line 88, in import_module
    return _bootstrap._gcd_import(name[level:], package, level)
           ~~~~~~~~~~~~~~~~~~~~~~^^^^^^^^^^^^^^^^^^^^^^^^^^^^^^
  File "<frozen importlib._bootstrap>", line 1387, in _gcd_import
  File "<frozen importlib._bootstrap>", line 1360, in _find_and_load
  File "<frozen importlib._bootstrap>", line 1331, in _find_and_load_unlocked
  File "<frozen importlib._bootstrap>", line 935, in _load_unlocked
  File "<frozen importlib._bootstrap_external>", line 1026, in exec_module
  File "<frozen importlib._bootstrap>", line 488, in _call_with_frames_removed
  File "/home/runezvdw/store.innovestraenterprises.co.ke/innotech/urls.py", line 9, in <module>
    path('auth/', include('Account.urls')),
                  ~~~~~~~^^^^^^^^^^^^^^^^
  File "/home/runezvdw/virtualenv/store.innovestraenterprises.co.ke/3.13/lib/python3.13/site-packages/django/urls/conf.py", line 39, in include
    urlconf_module = import_module(urlconf_module)
  File "/opt/alt/python313/lib64/python3.13/importlib/__init__.py", line 88, in import_module
    return _bootstrap._gcd_import(name[level:], package, level)
           ~~~~~~~~~~~~~~~~~~~~~~^^^^^^^^^^^^^^^^^^^^^^^^^^^^^^
  File "<frozen importlib._bootstrap>", line 1387, in _gcd_import
  File "<frozen importlib._bootstrap>", line 1360, in _find_and_load
  File "<frozen importlib._bootstrap>", line 1331, in _find_and_load_unlocked
  File "<frozen importlib._bootstrap>", line 935, in _load_unlocked
  File "<frozen importlib._bootstrap_external>", line 1026, in exec_module
  File "<frozen importlib._bootstrap>", line 488, in _call_with_frames_removed
  File "/home/runezvdw/store.innovestraenterprises.co.ke/Account/urls.py", line 2, in <module>
    from . import views
  File "/home/runezvdw/store.innovestraenterprises.co.ke/Account/views.py", line 10, in <module>
    from .models import PendingRegistration, CustomUser, PasswordReset
ImportError: cannot import name 'PendingRegistration' from 'Account.models' (/home/runezvdw/store.innovestraenterprises.co.ke/Account/models.py)
